<?xml version="1.0"?>
<robot name="kitty_bot" xmlns:xacro="http://ros.org/wiki/xacro">

    <!-- Define robot constants -->
    <xacro:property name="base_width" value="0.31" />
    <xacro:property name="base_length" value="0.42" />
    <xacro:property name="base_radius" value="0.08"/>
    <xacro:property name="base_height" value="0.14" />


    <xacro:property name="wheel_radius" value="0.024" />
    <xacro:property name="wheel_width" value="0.02" />
    <xacro:property name="wheel_ygap" value="-0.02" />
    <xacro:property name="wheel_zoff" value="0.03" />
    <xacro:property name="wheel_xoff" value="0.00" />

    <xacro:property name="caster_radius" value="0.01"/>
    <xacro:property name="caster_xoff" value="0.06" />

    <!-- Robot Base -->
    <link name="base_link">
        <visual>
            <origin xyz="0 0 ${base_height/2}" rpy="0 0 0" />
            <geometry>
                <cylinder radius="${base_radius}" length="${base_height}"/>
            </geometry>
            <material name="Cyan">
                <color rgba="0 1.0 1.0 1.0" />
            </material>
        </visual>
    </link>

    <!-- Robot Footprint -->
    <link name="base_footprint" />

    <joint name="base_joint" type="fixed">
        <parent link="base_link" />
        <child link="base_footprint" />
        <origin xyz="0.0 0.0 ${-(wheel_radius+wheel_zoff)}" rpy="0 0 0" />
    </joint>

    <!-- Wheels -->
    <xacro:macro name="wheel" params="prefix x_reflect y_reflect">
        <link name="${prefix}_link">
            <visual>
                <origin xyz="0 0 0" rpy="${pi/2} 0 0" />
                <geometry>
                    <cylinder radius="${wheel_radius}" length="${wheel_width}" />
                </geometry>
                <material name="Gray">
                    <color rgba="0.5 0.5 0.5 1.0" />
                </material>
            </visual>
        </link>

        <joint name="${prefix}_joint" type="continuous">
            <parent link="base_link" />
            <child link="${prefix}_link" />
            <origin
                xyz="${x_reflect*wheel_xoff} ${y_reflect*(base_radius+wheel_ygap)} ${-wheel_zoff}"
                rpy="0 0 0" />
            <axis xyz="0 1 0" />
        </joint>
    </xacro:macro>

    <xacro:wheel prefix="drivewhl_l" x_reflect="-1" y_reflect="1" />
    <xacro:wheel prefix="drivewhl_r" x_reflect="-1" y_reflect="-1" />

    <!-- Caster Wheel -->
    <link name="front_caster">
        <visual>
            <geometry>
                <sphere radius="${caster_radius}" />
            </geometry>
            <material name="Cyan">
                <color rgba="0 1.0 1.0 1.0" />
            </material>
        </visual>
    </link>

    <joint name="front_caster_joint" type="fixed">
        <parent link="base_link" />
        <child link="front_caster" />
        <origin xyz="${caster_xoff} 0.0 ${-(wheel_radius+wheel_zoff-caster_radius)}" rpy="0 0 0" />
    </joint>

    <link name="behind_caster">
        <visual>
            <geometry>
                <sphere radius="${caster_radius}" />
            </geometry>
            <material name="Cyan">
                <color rgba="0 1.0 1.0 1.0" />
            </material>
        </visual>
    </link>

    <joint name="behind_caster_joint" type="fixed">
        <parent link="base_link" />
        <child link="behind_caster" />
        <origin xyz="${-caster_xoff} 0.0 ${-(wheel_radius+wheel_zoff-caster_radius)}" rpy="0 0 0" />
    </joint>

</robot>